Workbook

Sheet Final Summary 
A1: Metrics | B1: Model 1 - GDP growth | C1: Model 2 - Unemployment | D1: Model 3 - Income growth
A2: Training Results (1980-2015)
A3: R2 | B3: ='Training Data'!P6 -> 0.20846616 | C3: ='Training Data'!P29 -> 0.24280363 | D3: ='Training Data'!P54 -> 0.99874142
A4: Adjusted R2 | B4: ='Training Data'!P7 -> 0.13425986 | C4: ='Training Data'!P30 -> 0.1739676 | D4: ='Training Data'!P55 -> 0.99862701
A5: F-statistic P-value | B5: ='Training Data'!T13 -> 0.055187726 | C5: ='Training Data'!T36 -> 0.025412066 | D5: ='Training Data'!T61 -> 6.5860689e-48
A6: Immigration Coefficient | B6: ='Training Data'!P19 -> -2.4616384e-06 | C6: ='Training Data'!P43 -> -3.6248466e-06 | D6: ='Training Data'!P67 -> -5.4751729e-05
A7: Immigration P-value | B7: ='Training Data'!S19 -> 0.52651081 | C7: ='Training Data'!S43 -> 0.73593184 | D7: ='Training Data'!S67 -> 0.34840962
A8: Immigration Significant | B8: NO | C8: NO | D8: NO
A10: Testing Results (2016-2021)
A11: MAE | B11: ='Testing Data'!B10 -> 7.9909778 | C11: ='Testing Data'!B17 -> 459064.64 | D11: ='Testing Data'!B23 -> 3450.0772
A12: RMSE | B12: ='Testing Data'!B11 -> 8.4314093 | C12: ='Testing Data'!B18 -> 478921.59 | D12: ='Testing Data'!B24 -> 3457.5303
A13: MAPE | B13: ='Testing Data'!B12 -> 2.2091694 | C13: ='Testing Data'!B19 -> 8420.2285 | D13: ='Testing Data'!B25 -> 0.16480243
A14: Conclusion | B14: NO, Significant impact | C14: NO, Significant impact | D14: NO, Significant impact
A16: Critical Factor Ranking
A17: Variable | B17: Model | C17: Coefficient | D17: P-value | E17: Effect on DV
A18: Net immigration | B18: Model 3 | C18: =$D$6 -> -5.4751729e-05 | D18: =$D$7 -> 0.34840962 | E18: No significant effect on Income Growth
A19: Net immigration | B19: Model 2 | C19: =$C$6 -> -3.6248466e-06 | D19: =$C$7 -> 0.73593184 | E19: No significant effect on Unemployment
A20: Net immigration | B20: Model 1 | C20: =$B$6 -> -2.4616384e-06 | D20: =$B$7 -> 0.52651081 | E20: No significant effect on GDP Growth
A21: Unemployment Rate | B21: Model 1 | C21: ='Training Data'!$P$20 -> 0.10181284 | D21: ='Training Data'!$S$20 -> 0.10370822 | E21: Marginal positive effect on GDP Growth (not significant)
A22: GDP Growth Ranking | B22: Model 2 | C22: ='Training Data'!$P$42 -> 0.76536121 | D22: ='Training Data'!$S$42 -> 0.10969376 | E22: Marginal positive effect on Unemployment (not significant)
A23: GDP Nominal | B23: Model 3 | C23: ='Training Data'!$P$68 -> 0.84797794 | D23: ='Training Data'!$S$68 -> 1.0242023e-47 | E23: Strong positive effect on Income Growth (HIGHLY SIGNIFICANT)
A24: Unemployment Rate | B24: Model 3 | C24: ='Training Data'!$P$69 -> 3.2317381 | D24: ='Training Data'!$S$69 -> 0.025316355 | E24: Significant positive effect on Income Growth
A28: Critical Factor Ranking based on P-value
A29: Variable | B29: Model | C29: Coefficient | D29: P-value | E29: Effect on DV
A30: GDP Nominal | B30: Model 3 | C30: ='Training Data'!$P$68 -> 0.84797794 | D30: ='Training Data'!$S$68 -> 1.0242023e-47 | E30: EXTREMELY strong positive effect on Income Growth. Each $1B increase in GDP → 0.85% increase in personal income growth. HIGHLY SIGNIFICANT.
A31: Unemployment Rate | B31: Model 3 | C31: ='Training Data'!$P$69 -> 3.2317381 | D31: ='Training Data'!$S$69 -> 0.025316355 | E31: Significant positive effect on Income Growth. 1 percentage point increase in unemployment → 3.23% increase in income growth (counterintuitive - may reflect wage inflation during tight labor markets).
A32: Unemployment Rate | B32: Model 1 | C32: ='Training Data'!$P$20 -> 0.10181284 | D32: ='Training Data'!$S$20 -> 0.10370822 | E32: Marginal effect on GDP Growth. Not statistically significant at 5% level, but close (marginal at 10% level).
A33: GDP Growth Ranking | B33: Model 2 | C33: ='Training Data'!$P$42 -> 0.76536121 | D33: ='Training Data'!$S$42 -> 0.10969376 | E33: Marginal effect on Unemployment. Not significant, but shows trend: higher GDP growth → higher unemployment
A34: Net immigration | B34: Model 3 | C34: =$D$6 -> -5.4751729e-05 | D34: =$D$7 -> 0.34840962 | E34: No significant effect on Income Growth
A35: Net immigration | B35: Model 1 | C35: =$B$6 -> -2.4616384e-06 | D35: =$B$7 -> 0.52651081 | E35: No significant effect on GDP Growth
A36: Net immigration | B36: Model 2 | C36: =$C$6 -> -3.6248466e-06 | D36: =$C$7 -> 0.73593184 | E36: No significant effect on Unemployment

Sheet Master Dataset
A1: Year | B1: Net Immigration | C1: Immigration Rate | D1: GDP Nominal | E1: GDP Growth Rate | F1: Personal Income | G1: Unemployment Rate | H1: Immigration Lag1 | I1: GDP lag1 | K1: Net Immigration | L1: =G1 -> Unemployment Rate | M1: =H1 -> Immigration Lag1 | O1: =G1 -> Unemployment Rate | P1: =E1 -> GDP Growth Rate | Q1: =B1 -> Net Immigration | R1: =H1 -> Immigration Lag1 | T1: =F1 -> Personal Income | U1: =B1 -> Net Immigration | V1: =D1 -> GDP Nominal | W1: =G1 -> Unemployment Rate
A2: 1980 | B2: =VLOOKUP(A2,'Raw_Imigration data'!A:G, 7, FALSE) -> -5813 | C2: =VLOOKUP(A2,'Raw_Imigration data'!A:H, 8, FALSE) -> -2325.2 | D2: ='Raw_Gross Domestic Product '!B3 -> 2857.3 | F2: ='Raw_Personal Income and Its Dis'!C3 -> 2324.5 | G2: =Raw_Unemployment!B2 -> 86.1 | K2: =B2 -> -5813 | L2: =G2 -> 86.1 | M2: =H2 -> 0 | O2: =G2 -> 86.1 | P2: =E2 -> 0 | Q2: =B2 -> -5813 | R2: =H2 -> 0 | T2: =F2 -> 2324.5 | U2: =B2 -> -5813 | V2: =D2 -> 2857.3 | W2: =G2 -> 86.1
A3: 1981 | B3: =VLOOKUP(A3,'Raw_Imigration data'!A:G, 7, FALSE) -> -86988 | C3: =VLOOKUP(A3,'Raw_Imigration data'!A:H, 8, FALSE) -> -34795.2 | D3: ='Raw_Gross Domestic Product '!C3 -> 3207 | E3: =((D3-D2)/D2)*100 -> 12.238827 | F3: ='Raw_Personal Income and Its Dis'!D3 -> 2603.2 | G3: =Raw_Unemployment!B3 -> 91.4 | H3: =B2 -> -5813 | I3: =E2 -> 0 | K3: =B3 -> -86988 | L3: =G3 -> 91.4 | M3: =H3 -> -5813 | O3: =G3 -> 91.4 | P3: =E3 -> 12.238827 | Q3: =B3 -> -86988 | R3: =H3 -> -5813 | T3: =F3 -> 2603.2 | U3: =B3 -> -86988 | V3: =D3 -> 3207 | W3: =G3 -> 91.4
A4: 1982 | B4: =VLOOKUP(A4,'Raw_Imigration data'!A:G, 7, FALSE) -> -196068 | C4: =VLOOKUP(A4,'Raw_Imigration data'!A:H, 8, FALSE) -> -78427.2 | D4: ='Raw_Gross Domestic Product '!D3 -> 3343.8 | E4: =((D4-D3)/D3)*100 -> 4.2656688 | F4: ='Raw_Personal Income and Its Dis'!E3 -> 2789.5 | G4: =Raw_Unemployment!B4 -> 116.5 | H4: =B3 -> -86988 | I4: =E3 -> 12.238827 | K4: =B4 -> -196068 | L4: =G4 -> 116.5 | M4: =H4 -> -86988 | O4: =G4 -> 116.5 | P4: =E4 -> 4.2656688 | Q4: =B4 -> -196068 | R4: =H4 -> -86988 | T4: =F4 -> 2789.5 | U4: =B4 -> -196068 | V4: =D4 -> 3343.8 | W4: =G4 -> 116.5
A5: 1983 | B5: =VLOOKUP(A5,'Raw_Imigration data'!A:G, 7, FALSE) -> -339541 | C5: =VLOOKUP(A5,'Raw_Imigration data'!A:H, 8, FALSE) -> -135816.4 | D5: ='Raw_Gross Domestic Product '!E3 -> 3634 | E5: =((D5-D4)/D4)*100 -> 8.6787487 | F5: ='Raw_Personal Income and Its Dis'!F3 -> 2981.7 | G5: =Raw_Unemployment!B5 -> 115.2 | H5: =B4 -> -196068 | I5: =E4 -> 4.2656688 | K5: =B5 -> -339541 | L5: =G5 -> 115.2 | M5: =H5 -> -196068 | O5: =G5 -> 115.2 | P5: =E5 -> 8.6787487 | Q5: =B5 -> -339541 | R5: =H5 -> -196068 | T5: =F5 -> 2981.7 | U5: =B5 -> -339541 | V5: =D5 -> 3634 | W5: =G5 -> 115.2
A6: 1984 | B6: =VLOOKUP(A6,'Raw_Imigration data'!A:G, 7, FALSE) -> -316325 | C6: =VLOOKUP(A6,'Raw_Imigration data'!A:H, 8, FALSE) -> -126530 | D6: ='Raw_Gross Domestic Product '!F3 -> 4037.6 | E6: =((D6-D5)/D5)*100 -> 11.106219 | F6: ='Raw_Personal Income and Its Dis'!G3 -> 3288.7 | G6: =Raw_Unemployment!B6 -> 90.1 | H6: =B5 -> -339541 | I6: =E5 -> 8.6787487 | K6: =B6 -> -316325 | L6: =G6 -> 90.1 | M6: =H6 -> -339541 | O6: =G6 -> 90.1 | P6: =E6 -> 11.106219 | Q6: =B6 -> -316325 | R6: =H6 -> -339541 | T6: =F6 -> 3288.7 | U6: =B6 -> -316325 | V6: =D6 -> 4037.6 | W6: =G6 -> 90.1
A7: 1985 | B7: =VLOOKUP(A7,'Raw_Imigration data'!A:G, 7, FALSE) -> -428548 | C7: =VLOOKUP(A7,'Raw_Imigration data'!A:H, 8, FALSE) -> -171419.2 | D7: ='Raw_Gross Domestic Product '!G3 -> 4339 | E7: =((D7-D6)/D6)*100 -> 7.4648306 | F7: ='Raw_Personal Income and Its Dis'!H3 -> 3522.9 | G7: =Raw_Unemployment!B7 -> 86.3 | H7: =B6 -> -316325 | I7: =E6 -> 11.106219 | K7: =B7 -> -428548 | L7: =G7 -> 86.3 | M7: =H7 -> -316325 | O7: =G7 -> 86.3 | P7: =E7 -> 7.4648306 | Q7: =B7 -> -428548 | R7: =H7 -> -316325 | T7: =F7 -> 3522.9 | U7: =B7 -> -428548 | V7: =D7 -> 4339 | W7: =G7 -> 86.3
A8: 1986 | B8: =VLOOKUP(A8,'Raw_Imigration data'!A:G, 7, FALSE) -> -948739 | C8: =VLOOKUP(A8,'Raw_Imigration data'!A:H, 8, FALSE) -> -379495.6 | D8: ='Raw_Gross Domestic Product '!H3 -> 4579.6 | E8: =((D8-D7)/D7)*100 -> 5.5450565 | F8: ='Raw_Personal Income and Its Dis'!I3 -> 3731.2 | G8: =Raw_Unemployment!B8 -> 84 | H8: =B7 -> -428548 | I8: =E7 -> 7.4648306 | K8: =B8 -> -948739 | L8: =G8 -> 84 | M8: =H8 -> -428548 | O8: =G8 -> 84 | P8: =E8 -> 5.5450565 | Q8: =B8 -> -948739 | R8: =H8 -> -428548 | T8: =F8 -> 3731.2 | U8: =B8 -> -948739 | V8: =D8 -> 4579.6 | W8: =G8 -> 84
A9: 1987 | B9: =VLOOKUP(A9,'Raw_Imigration data'!A:G, 7, FALSE) -> -451122 | C9: =VLOOKUP(A9,'Raw_Imigration data'!A:H, 8, FALSE) -> -180448.8 | D9: ='Raw_Gross Domestic Product '!I3 -> 4855.2 | E9: =((D9-D8)/D8)*100 -> 6.0179928 | F9: ='Raw_Personal Income and Its Dis'!J3 -> 3946.8 | G9: =Raw_Unemployment!B9 -> 74.1 | H9: =B8 -> -948739 | I9: =E8 -> 5.5450565 | K9: =B9 -> -451122 | L9: =G9 -> 74.1 | M9: =H9 -> -948739 | O9: =G9 -> 74.1 | P9: =E9 -> 6.0179928 | Q9: =B9 -> -451122 | R9: =H9 -> -948739 | T9: =F9 -> 3946.8 | U9: =B9 -> -451122 | V9: =D9 -> 4855.2 | W9: =G9 -> 74.1
A10: 1988 | B10: =VLOOKUP(A10,'Raw_Imigration data'!A:G, 7, FALSE) -> -219790 | C10: =VLOOKUP(A10,'Raw_Imigration data'!A:H, 8, FALSE) -> -87916 | D10: ='Raw_Gross Domestic Product '!J3 -> 5236.4 | E10: =((D10-D9)/D9)*100 -> 7.8513758 | F10: ='Raw_Personal Income and Its Dis'!K3 -> 4280 | G10: =Raw_Unemployment!B10 -> 65.9 | H10: =B9 -> -451122 | I10: =E9 -> 6.0179928 | K10: =B10 -> -219790 | L10: =G10 -> 65.9 | M10: =H10 -> -451122 | O10: =G10 -> 65.9 | P10: =E10 -> 7.8513758 | Q10: =B10 -> -219790 | R10: =H10 -> -451122 | T10: =F10 -> 4280 | U10: =B10 -> -219790 | V10: =D10 -> 5236.4 | W10: =G10 -> 65.9
A11: 1989 | B11: =VLOOKUP(A11,'Raw_Imigration data'!A:G, 7, FALSE) -> 331925 | C11: =VLOOKUP(A11,'Raw_Imigration data'!A:H, 8, FALSE) -> 132770 | D11: ='Raw_Gross Domestic Product '!K3 -> 5641.6 | E11: =((D11-D10)/D10)*100 -> 7.7381407 | F11: ='Raw_Personal Income and Its Dis'!L3 -> 4621 | G11: =Raw_Unemployment!B11 -> 63.1 | H11: =B10 -> -219790 | I11: =E10 -> 7.8513758 | K11: =B11 -> 331925 | L11: =G11 -> 63.1 | M11: =H11 -> -219790 | O11: =G11 -> 63.1 | P11: =E11 -> 7.7381407 | Q11: =B11 -> 331925 | R11: =H11 -> -219790 | T11: =F11 -> 4621 | U11: =B11 -> 331925 | V11: =D11 -> 5641.6 | W11: =G11 -> 63.1
A12: 1990 | B12: =VLOOKUP(A12,'Raw_Imigration data'!A:G, 7, FALSE) -> 605366 | C12: =VLOOKUP(A12,'Raw_Imigration data'!A:H, 8, FALSE) -> 242146.4 | D12: ='Raw_Gross Domestic Product '!L3 -> 5963.1 | E12: =((D12-D11)/D11)*100 -> 5.6987379 | F12: ='Raw_Personal Income and Its Dis'!M3 -> 4913.3 | G12: =Raw_Unemployment!B12 -> 67.4 | H12: =B11 -> 331925 | I12: =E11 -> 7.7381407 | K12: =B12 -> 605366 | L12: =G12 -> 67.4 | M12: =H12 -> 331925 | O12: =G12 -> 67.4 | P12: =E12 -> 5.6987379 | Q12: =B12 -> 605366 | R12: =H12 -> 331925 | T12: =F12 -> 4913.3 | U12: =B12 -> 605366 | V12: =D12 -> 5963.1 | W12: =G12 -> 67.4
A13: 1991 | B13: =VLOOKUP(A13,'Raw_Imigration data'!A:G, 7, FALSE) -> 845690 | C13: =VLOOKUP(A13,'Raw_Imigration data'!A:H, 8, FALSE) -> 338276 | D13: ='Raw_Gross Domestic Product '!M3 -> 6158.1 | E13: =((D13-D12)/D12)*100 -> 3.2701112 | F13: ='Raw_Personal Income and Its Dis'!N3 -> 5089.9 | G13: =Raw_Unemployment!B13 -> 82.2 | H13: =B12 -> 605366 | I13: =E12 -> 5.6987379 | K13: =B13 -> 845690 | L13: =G13 -> 82.2 | M13: =H13 -> 605366 | O13: =G13 -> 82.2 | P13: =E13 -> 3.2701112 | Q13: =B13 -> 845690 | R13: =H13 -> 605366 | T13: =F13 -> 5089.9 | U13: =B13 -> 845690 | V13: =D13 -> 6158.1 | W13: =G13 -> 82.2
A14: 1992 | B14: =VLOOKUP(A14,'Raw_Imigration data'!A:G, 7, FALSE) -> -60507 | C14: =VLOOKUP(A14,'Raw_Imigration data'!A:H, 8, FALSE) -> -24202.8 | D14: ='Raw_Gross Domestic Product '!N3 -> 6520.3 | E14: =((D14-D13)/D13)*100 -> 5.8816843 | F14: ='Raw_Personal Income and Its Dis'!O3 -> 5417.5 | G14: =Raw_Unemployment!B14 -> 89.9 | H14: =B13 -> 845690 | I14: =E13 -> 3.2701112 | K14: =B14 -> -60507 | L14: =G14 -> 89.9 | M14: =H14 -> 845690 | O14: =G14 -> 89.9 | P14: =E14 -> 5.8816843 | Q14: =B14 -> -60507 | R14: =H14 -> 845690 | T14: =F14 -> 5417.5 | U14: =B14 -> -60507 | V14: =D14 -> 6520.3 | W14: =G14 -> 89.9
A15: 1993 | B15: =VLOOKUP(A15,'Raw_Imigration data'!A:G, 7, FALSE) -> -267855 | C15: =VLOOKUP(A15,'Raw_Imigration data'!A:H, 8, FALSE) -> -107142 | D15: ='Raw_Gross Domestic Product '!O3 -> 6858.6 | E15: =((D15-D14)/D14)*100 -> 5.1884116 | F15: ='Raw_Personal Income and Its Dis'!P3 -> 5652.9 | G15: =Raw_Unemployment!B15 -> 82.9 | H15: =B14 -> -60507 | I15: =E14 -> 5.8816843 | K15: =B15 -> -267855 | L15: =G15 -> 82.9 | M15: =H15 -> -60507 | O15: =G15 -> 82.9 | P15: =E15 -> 5.1884116 | Q15: =B15 -> -267855 | R15: =H15 -> -60507 | T15: =F15 -> 5652.9 | U15: =B15 -> -267855 | V15: =D15 -> 6858.6 | W15: =G15 -> 82.9
A16: 1994 | B16: =VLOOKUP(A16,'Raw_Imigration data'!A:G, 7, FALSE) -> -159108 | C16: =VLOOKUP(A16,'Raw_Imigration data'!A:H, 8, FALSE) -> -63643.2 | D16: ='Raw_Gross Domestic Product '!P3 -> 7287.2 | E16: =((D16-D15)/D15)*100 -> 6.2490887 | F16: ='Raw_Personal Income and Its Dis'!Q3 -> 5940.9 | G16: =Raw_Unemployment!B16 -> 73.2 | H16: =B15 -> -267855 | I16: =E15 -> 5.1884116 | K16: =B16 -> -159108 | L16: =G16 -> 73.2 | M16: =H16 -> -267855 | O16: =G16 -> 73.2 | P16: =E16 -> 6.2490887 | Q16: =B16 -> -159108 | R16: =H16 -> -267855 | T16: =F16 -> 5940.9 | U16: =B16 -> -159108 | V16: =D16 -> 7287.2 | W16: =G16 -> 73.2
A17: 1995 | B17: =VLOOKUP(A17,'Raw_Imigration data'!A:G, 7, FALSE) -> -545538 | C17: =VLOOKUP(A17,'Raw_Imigration data'!A:H, 8, FALSE) -> -218215.2 | D17: ='Raw_Gross Domestic Product '!Q3 -> 7639.7 | E17: =((D17-D16)/D16)*100 -> 4.8372489 | F17: ='Raw_Personal Income and Its Dis'!R3 -> 6283.4 | G17: =Raw_Unemployment!B17 -> 67.1 | H17: =B16 -> -159108 | I17: =E16 -> 6.2490887 | K17: =B17 -> -545538 | L17: =G17 -> 67.1 | M17: =H17 -> -159108 | O17: =G17 -> 67.1 | P17: =E17 -> 4.8372489 | Q17: =B17 -> -545538 | R17: =H17 -> -159108 | T17: =F17 -> 6283.4 | U17: =B17 -> -545538 | V17: =D17 -> 7639.7 | W17: =G17 -> 67.1
A18: 1996 | B18: =VLOOKUP(A18,'Raw_Imigration data'!A:G, 7, FALSE) -> -652127 | C18: =VLOOKUP(A18,'Raw_Imigration data'!A:H, 8, FALSE) -> -260850.8 | D18: ='Raw_Gross Domestic Product '!R3 -> 8073.1 | E18: =((D18-D17)/D17)*100 -> 5.6729976 | F18: ='Raw_Personal Income and Its Dis'!S3 -> 6666.2 | G18: =Raw_Unemployment!B18 -> 64.9 | H18: =B17 -> -545538 | I18: =E17 -> 4.8372489 | K18: =B18 -> -652127 | L18: =G18 -> 64.9 | M18: =H18 -> -545538 | O18: =G18 -> 64.9 | P18: =E18 -> 5.6729976 | Q18: =B18 -> -652127 | R18: =H18 -> -545538 | T18: =F18 -> 6666.2 | U18: =B18 -> -652127 | V18: =D18 -> 8073.1 | W18: =G18 -> 64.9
A19: 1997 | B19: =VLOOKUP(A19,'Raw_Imigration data'!A:G, 7, FALSE) -> -687616 | C19: =VLOOKUP(A19,'Raw_Imigration data'!A:H, 8, FALSE) -> -275046.4 | D19: ='Raw_Gross Domestic Product '!S3 -> 8577.6 | E19: =((D19-D18)/D18)*100 -> 6.2491484 | F19: ='Raw_Personal Income and Its Dis'!T3 -> 7074 | G19: =Raw_Unemployment!B19 -> 59.3 | H19: =B18 -> -652127 | I19: =E18 -> 5.6729976 | K19: =B19 -> -687616 | L19: =G19 -> 59.3 | M19: =H19 -> -652127 | O19: =G19 -> 59.3 | P19: =E19 -> 6.2491484 | Q19: =B19 -> -687616 | R19: =H19 -> -652127 | T19: =F19 -> 7074 | U19: =B19 -> -687616 | V19: =D19 -> 8577.6 | W19: =G19 -> 59.3
A20: 1998 | B20: =VLOOKUP(A20,'Raw_Imigration data'!A:G, 7, FALSE) -> -1015022 | C20: =VLOOKUP(A20,'Raw_Imigration data'!A:H, 8, FALSE) -> -406008.8 | D20: ='Raw_Gross Domestic Product '!T3 -> 9062.8 | E20: =((D20-D19)/D19)*100 -> 5.6565939 | F20: ='Raw_Personal Income and Its Dis'!U3 -> 7588.4 | G20: =Raw_Unemployment!B20 -> 54 | H20: =B19 -> -687616 | I20: =E19 -> 6.2491484 | K20: =B20 -> -1015022 | L20: =G20 -> 54 | M20: =H20 -> -687616 | O20: =G20 -> 54 | P20: =E20 -> 5.6565939 | Q20: =B20 -> -1015022 | R20: =H20 -> -687616 | T20: =F20 -> 7588.4 | U20: =B20 -> -1015022 | V20: =D20 -> 9062.8 | W20: =G20 -> 54
A21: 1999 | B21: =VLOOKUP(A21,'Raw_Imigration data'!A:G, 7, FALSE) -> -1027905 | C21: =VLOOKUP(A21,'Raw_Imigration data'!A:H, 8, FALSE) -> -411162 | D21: ='Raw_Gross Domestic Product '!U3 -> 9631.2 | E21: =((D21-D20)/D20)*100 -> 6.2717924 | F21: ='Raw_Personal Income and Its Dis'!V3 -> 7978.6 | G21: =Raw_Unemployment!B21 -> 50.6 | H21: =B20 -> -1015022 | I21: =E20 -> 5.6565939 | K21: =B21 -> -1027905 | L21: =G21 -> 50.6 | M21: =H21 -> -1015022 | O21: =G21 -> 50.6 | P21: =E21 -> 6.2717924 | Q21: =B21 -> -1027905 | R21: =H21 -> -1015022 | T21: =F21 -> 7978.6 | U21: =B21 -> -1027905 | V21: =D21 -> 9631.2 | W21: =G21 -> 50.6
A22: 2000 | B22: =VLOOKUP(A22,'Raw_Imigration data'!A:G, 7, FALSE) -> -951176 | C22: =VLOOKUP(A22,'Raw_Imigration data'!A:H, 8, FALSE) -> -380470.4 | D22: ='Raw_Gross Domestic Product '!V3 -> 10251 | E22: =((D22-D21)/D21)*100 -> 6.4353352 | F22: ='Raw_Personal Income and Its Dis'!W3 -> 8621.3 | G22: =Raw_Unemployment!B22 -> 47.6 | H22: =B21 -> -1027905 | I22: =E21 -> 6.2717924 | K22: =B22 -> -951176 | L22: =G22 -> 47.6 | M22: =H22 -> -1027905 | O22: =G22 -> 47.6 | P22: =E22 -> 6.4353352 | Q22: =B22 -> -951176 | R22: =H22 -> -1027905 | T22: =F22 -> 8621.3 | U22: =B22 -> -951176 | V22: =D22 -> 10251 | W22: =G22 -> 47.6
A23: 2001 | B23: =VLOOKUP(A23,'Raw_Imigration data'!A:G, 7, FALSE) -> -410575 | C23: =VLOOKUP(A23,'Raw_Imigration data'!A:H, 8, FALSE) -> -164230 | D23: ='Raw_Gross Domestic Product '!W3 -> 10581.9 | E23: =((D23-D22)/D22)*100 -> 3.2279778 | F23: ='Raw_Personal Income and Its Dis'!X3 -> 8993.1 | G23: =Raw_Unemployment!B23 -> 56.9 | H23: =B22 -> -951176 | I23: =E22 -> 6.4353352 | K23: =B23 -> -410575 | L23: =G23 -> 56.9 | M23: =H23 -> -951176 | O23: =G23 -> 56.9 | P23: =E23 -> 3.2279778 | Q23: =B23 -> -410575 | R23: =H23 -> -951176 | T23: =F23 -> 8993.1 | U23: =B23 -> -410575 | V23: =D23 -> 10581.9 | W23: =G23 -> 56.9
A24: 2002 | B24: =VLOOKUP(A24,'Raw_Imigration data'!A:G, 7, FALSE) -> -91143 | C24: =VLOOKUP(A24,'Raw_Imigration data'!A:H, 8, FALSE) -> -36457.2 | D24: ='Raw_Gross Domestic Product '!X3 -> 10929.1 | E24: =((D24-D23)/D23)*100 -> 3.2810743 | F24: ='Raw_Personal Income and Its Dis'!Y3 -> 9150 | G24: =Raw_Unemployment!B24 -> 69.4 | H24: =B23 -> -410575 | I24: =E23 -> 3.2279778 | K24: =B24 -> -91143 | L24: =G24 -> 69.4 | M24: =H24 -> -410575 | O24: =G24 -> 69.4 | P24: =E24 -> 3.2810743 | Q24: =B24 -> -91143 | R24: =H24 -> -410575 | T24: =F24 -> 9150 | U24: =B24 -> -91143 | V24: =D24 -> 10929.1 | W24: =G24 -> 69.4
A25: 2003 | B25: =VLOOKUP(A25,'Raw_Imigration data'!A:G, 7, FALSE) -> -424564 | C25: =VLOOKUP(A25,'Raw_Imigration data'!A:H, 8, FALSE) -> -169825.6 | D25: ='Raw_Gross Domestic Product '!Y3 -> 11456.5 | E25: =((D25-D24)/D24)*100 -> 4.825649 | F25: ='Raw_Personal Income and Its Dis'!Z3 -> 9481.8 | G25: =Raw_Unemployment!B25 -> 71.9 | H25: =B24 -> -91143 | I25: =E24 -> 3.2810743 | K25: =B25 -> -424564 | L25: =G25 -> 71.9 | M25: =H25 -> -91143 | O25: =G25 -> 71.9 | P25: =E25 -> 4.825649 | Q25: =B25 -> -424564 | R25: =H25 -> -91143 | T25: =F25 -> 9481.8 | U25: =B25 -> -424564 | V25: =D25 -> 11456.5 | W25: =G25 -> 71.9
A26: 2004 | B26: =VLOOKUP(A26,'Raw_Imigration data'!A:G, 7, FALSE) -> -396518 | C26: =VLOOKUP(A26,'Raw_Imigration data'!A:H, 8, FALSE) -> -158607.2 | D26: ='Raw_Gross Domestic Product '!Z3 -> 12217.2 | E26: =((D26-D25)/D25)*100 -> 6.6398987 | F26: ='Raw_Personal Income and Its Dis'!AA3 -> 10015.9 | G26: =Raw_Unemployment!B26 -> 66.5 | H26: =B25 -> -424564 | I26: =E25 -> 4.825649 | K26: =B26 -> -396518 | L26: =G26 -> 66.5 | M26: =H26 -> -424564 | O26: =G26 -> 66.5 | P26: =E26 -> 6.6398987 | Q26: =B26 -> -396518 | R26: =H26 -> -424564 | T26: =F26 -> 10015.9 | U26: =B26 -> -396518 | V26: =D26 -> 12217.2 | W26: =G26 -> 66.5
A27: 2005 | B27: =VLOOKUP(A27,'Raw_Imigration data'!A:G, 7, FALSE) -> -167356 | C27: =VLOOKUP(A27,'Raw_Imigration data'!A:H, 8, FALSE) -> -66942.4 | D27: ='Raw_Gross Domestic Product '!AA3 -> 13039.2 | E27: =((D27-D26)/D26)*100 -> 6.7282192 | F27: ='Raw_Personal Income and Its Dis'!AB3 -> 10546.1 | G27: =Raw_Unemployment!B27 -> 61 | H27: =B26 -> -396518 | I27: =E26 -> 6.6398987 | K27: =B27 -> -167356 | L27: =G27 -> 61 | M27: =H27 -> -396518 | O27: =G27 -> 61 | P27: =E27 -> 6.7282192 | Q27: =B27 -> -167356 | R27: =H27 -> -396518 | T27: =F27 -> 10546.1 | U27: =B27 -> -167356 | V27: =D27 -> 13039.2 | W27: =G27 -> 61
A28: 2006 | B28: =VLOOKUP(A28,'Raw_Imigration data'!A:G, 7, FALSE) -> -17132 | C28: =VLOOKUP(A28,'Raw_Imigration data'!A:H, 8, FALSE) -> -6852.8 | D28: ='Raw_Gross Domestic Product '!AB3 -> 13815.6 | E28: =((D28-D27)/D27)*100 -> 5.954353 | F28: ='Raw_Personal Income and Its Dis'!AC3 -> 11302 | G28: =Raw_Unemployment!B28 -> 55.3 | H28: =B27 -> -167356 | I28: =E27 -> 6.7282192 | K28: =B28 -> -17132 | L28: =G28 -> 55.3 | M28: =H28 -> -167356 | O28: =G28 -> 55.3 | P28: =E28 -> 5.954353 | Q28: =B28 -> -17132 | R28: =H28 -> -167356 | T28: =F28 -> 11302 | U28: =B28 -> -17132 | V28: =D28 -> 13815.6 | W28: =G28 -> 55.3
A29: 2007 | B29: =VLOOKUP(A29,'Raw_Imigration data'!A:G, 7, FALSE) -> -110139 | C29: =VLOOKUP(A29,'Raw_Imigration data'!A:H, 8, FALSE) -> -44055.6 | D29: ='Raw_Gross Domestic Product '!AC3 -> 14474.2 | E29: =((D29-D28)/D28)*100 -> 4.7670749 | F29: ='Raw_Personal Income and Its Dis'!AD3 -> 11932.1 | G29: =Raw_Unemployment!B29 -> 55.4 | H29: =B28 -> -17132 | I29: =E28 -> 5.954353 | K29: =B29 -> -110139 | L29: =G29 -> 55.4 | M29: =H29 -> -17132 | O29: =G29 -> 55.4 | P29: =E29 -> 4.7670749 | Q29: =B29 -> -110139 | R29: =H29 -> -17132 | T29: =F29 -> 11932.1 | U29: =B29 -> -110139 | V29: =D29 -> 14474.2 | W29: =G29 -> 55.4
A30: 2008 | B30: =VLOOKUP(A30,'Raw_Imigration data'!A:G, 7, FALSE) -> -3825 | C30: =VLOOKUP(A30,'Raw_Imigration data'!A:H, 8, FALSE) -> -1530 | D30: ='Raw_Gross Domestic Product '!AD3 -> 14769.9 | E30: =((D30-D29)/D29)*100 -> 2.0429454 | F30: ='Raw_Personal Income and Its Dis'!AE3 -> 12425.7 | G30: =Raw_Unemployment!B30 -> 69.6 | H30: =B29 -> -110139 | I30: =E29 -> 4.7670749 | K30: =B30 -> -3825 | L30: =G30 -> 69.6 | M30: =H30 -> -110139 | O30: =G30 -> 69.6 | P30: =E30 -> 2.0429454 | Q30: =B30 -> -3825 | R30: =H30 -> -110139 | T30: =F30 -> 12425.7 | U30: =B30 -> -3825 | V30: =D30 -> 14769.9 | W30: =G30 -> 69.6
A31: 2009 | B31: =VLOOKUP(A31,'Raw_Imigration data'!A:G, 7, FALSE) -> 243114 | C31: =VLOOKUP(A31,'Raw_Imigration data'!A:H, 8, FALSE) -> 97245.6 | D31: ='Raw_Gross Domestic Product '!AE3 -> 14478.1 | E31: =((D31-D30)/D30)*100 -> -1.9756396 | F31: ='Raw_Personal Income and Its Dis'!AF3 -> 12065.7 | G31: =Raw_Unemployment!B31 -> 111.4 | H31: =B30 -> -3825 | I31: =E30 -> 2.0429454 | K31: =B31 -> 243114 | L31: =G31 -> 111.4 | M31: =H31 -> -3825 | O31: =G31 -> 111.4 | P31: =E31 -> -1.9756396 | Q31: =B31 -> 243114 | R31: =H31 -> -3825 | T31: =F31 -> 12065.7 | U31: =B31 -> 243114 | V31: =D31 -> 14478.1 | W31: =G31 -> 111.4
A32: 2010 | B32: =VLOOKUP(A32,'Raw_Imigration data'!A:G, 7, FALSE) -> 261671 | C32: =VLOOKUP(A32,'Raw_Imigration data'!A:H, 8, FALSE) -> 104668.4 | D32: ='Raw_Gross Domestic Product '!AF3 -> 15049 | E32: =((D32-D31)/D31)*100 -> 3.943197 | F32: ='Raw_Personal Income and Its Dis'!AG3 -> 12556.6 | G32: =Raw_Unemployment!B32 -> 115.3 | H32: =B31 -> 243114 | I32: =E31 -> -1.9756396 | K32: =B32 -> 261671 | L32: =G32 -> 115.3 | M32: =H32 -> 243114 | O32: =G32 -> 115.3 | P32: =E32 -> 3.943197 | Q32: =B32 -> 261671 | R32: =H32 -> 243114 | T32: =F32 -> 12556.6 | U32: =B32 -> 261671 | V32: =D32 -> 15049 | W32: =G32 -> 115.3
A33: 2011 | B33: =VLOOKUP(A33,'Raw_Imigration data'!A:G, 7, FALSE) -> 405965 | C33: =VLOOKUP(A33,'Raw_Imigration data'!A:H, 8, FALSE) -> 162386 | D33: ='Raw_Gross Domestic Product '!AG3 -> 15599.7 | E33: =((D33-D32)/D32)*100 -> 3.6593794 | F33: ='Raw_Personal Income and Its Dis'!AH3 -> 13309.6 | G33: =Raw_Unemployment!B33 -> 107.2 | H33: =B32 -> 261671 | I33: =E32 -> 3.943197 | K33: =B33 -> 405965 | L33: =G33 -> 107.2 | M33: =H33 -> 261671 | O33: =G33 -> 107.2 | P33: =E33 -> 3.6593794 | Q33: =B33 -> 405965 | R33: =H33 -> 261671 | T33: =F33 -> 13309.6 | U33: =B33 -> 405965 | V33: =D33 -> 15599.7 | W33: =G33 -> 107.2
A34: 2012 | B34: =VLOOKUP(A34,'Raw_Imigration data'!A:G, 7, FALSE) -> 443126 | C34: =VLOOKUP(A34,'Raw_Imigration data'!A:H, 8, FALSE) -> 177250.4 | D34: ='Raw_Gross Domestic Product '!AH3 -> 16254 | E34: =((D34-D33)/D33)*100 -> 4.1943114 | F34: ='Raw_Personal Income and Its Dis'!AI3 -> 13917.8 | G34: =Raw_Unemployment!B34 -> 96.9 | H34: =B33 -> 405965 | I34: =E33 -> 3.6593794 | K34: =B34 -> 443126 | L34: =G34 -> 96.9 | M34: =H34 -> 405965 | O34: =G34 -> 96.9 | P34: =E34 -> 4.1943114 | Q34: =B34 -> 443126 | R34: =H34 -> 405965 | T34: =F34 -> 13917.8 | U34: =B34 -> 443126 | V34: =D34 -> 16254 | W34: =G34 -> 96.9
A35: 2013 | B35: =VLOOKUP(A35,'Raw_Imigration data'!A:G, 7, FALSE) -> 449288 | C35: =VLOOKUP(A35,'Raw_Imigration data'!A:H, 8, FALSE) -> 179715.2 | D35: ='Raw_Gross Domestic Product '!AI3 -> 16880.7 | E35: =((D35-D34)/D34)*100 -> 3.8556663 | F35: ='Raw_Personal Income and Its Dis'!AJ3 -> 14068.8 | G35: =Raw_Unemployment!B35 -> 88.3 | H35: =B34 -> 443126 | I35: =E34 -> 4.1943114 | K35: =B35 -> 449288 | L35: =G35 -> 88.3 | M35: =H35 -> 443126 | O35: =G35 -> 88.3 | P35: =E35 -> 3.8556663 | Q35: =B35 -> 449288 | R35: =H35 -> 443126 | T35: =F35 -> 14068.8 | U35: =B35 -> 449288 | V35: =D35 -> 16880.7 | W35: =G35 -> 88.3
A36: 2014 | B36: =VLOOKUP(A36,'Raw_Imigration data'!A:G, 7, FALSE) -> 517631 | C36: =VLOOKUP(A36,'Raw_Imigration data'!A:H, 8, FALSE) -> 207052.4 | D36: ='Raw_Gross Domestic Product '!AJ3 -> 17608.1 | E36: =((D36-D35)/D35)*100 -> 4.309063 | F36: ='Raw_Personal Income and Its Dis'!AK3 -> 14784.1 | G36: =Raw_Unemployment!B36 -> 73.9 | H36: =B35 -> 449288 | I36: =E35 -> 3.8556663 | K36: =B36 -> 517631 | L36: =G36 -> 73.9 | M36: =H36 -> 449288 | O36: =G36 -> 73.9 | P36: =E36 -> 4.309063 | Q36: =B36 -> 517631 | R36: =H36 -> 449288 | T36: =F36 -> 14784.1 | U36: =B36 -> 517631 | V36: =D36 -> 17608.1 | W36: =G36 -> 73.9
A37: 2015 | B37: =VLOOKUP(A37,'Raw_Imigration data'!A:G, 7, FALSE) -> 667012 | C37: =VLOOKUP(A37,'Raw_Imigration data'!A:H, 8, FALSE) -> 266804.8 | D37: ='Raw_Gross Domestic Product '!AK3 -> 18295 | E37: =((D37-D36)/D36)*100 -> 3.9010455 | F37: ='Raw_Personal Income and Its Dis'!AL3 -> 15473.7 | G37: =Raw_Unemployment!B37 -> 63.3 | H37: =B36 -> 517631 | I37: =E36 -> 4.309063 | K37: =B37 -> 667012 | L37: =G37 -> 63.3 | M37: =H37 -> 517631 | O37: =G37 -> 63.3 | P37: =E37 -> 3.9010455 | Q37: =B37 -> 667012 | R37: =H37 -> 517631 | T37: =F37 -> 15473.7 | U37: =B37 -> 667012 | V37: =D37 -> 18295 | W37: =G37 -> 63.3
A38: 2016 | B38: =VLOOKUP(A38,'Raw_Imigration data'!A:G, 7, FALSE) -> 829752 | C38: =VLOOKUP(A38,'Raw_Imigration data'!A:H, 8, FALSE) -> 331900.8 | D38: ='Raw_Gross Domestic Product '!AL3 -> 18804.9 | E38: =((D38-D37)/D37)*100 -> 2.7871003 | F38: ='Raw_Personal Income and Its Dis'!AM3 -> 15887.7 | G38: =Raw_Unemployment!B38 -> 58.5 | H38: =B37 -> 667012 | I38: =E37 -> 3.9010455 | K38: =B38 -> 829752 | L38: =G38 -> 58.5 | M38: =H38 -> 667012 | O38: =G38 -> 58.5 | P38: =E38 -> 2.7871003 | Q38: =B38 -> 829752 | R38: =H38 -> 667012 | T38: =F38 -> 15887.7 | U38: =B38 -> 829752 | V38: =D38 -> 18804.9 | W38: =G38 -> 58.5
A39: 2017 | B39: =VLOOKUP(A39,'Raw_Imigration data'!A:G, 7, FALSE) -> 796106 | C39: =VLOOKUP(A39,'Raw_Imigration data'!A:H, 8, FALSE) -> 318442.4 | D39: ='Raw_Gross Domestic Product '!AM3 -> 19612.1 | E39: =((D39-D38)/D38)*100 -> 4.2924982 | F39: ='Raw_Personal Income and Its Dis'!AN3 -> 16662.8 | G39: =Raw_Unemployment!B39 -> 52.3 | H39: =B38 -> 829752 | I39: =E38 -> 2.7871003 | K39: =B39 -> 796106 | L39: =G39 -> 52.3 | M39: =H39 -> 829752 | O39: =G39 -> 52.3 | P39: =E39 -> 4.2924982 | Q39: =B39 -> 796106 | R39: =H39 -> 829752 | T39: =F39 -> 16662.8 | U39: =B39 -> 796106 | V39: =D39 -> 19612.1 | W39: =G39 -> 52.3
A40: 2018 | B40: =VLOOKUP(A40,'Raw_Imigration data'!A:G, 7, FALSE) -> 631502 | C40: =VLOOKUP(A40,'Raw_Imigration data'!A:H, 8, FALSE) -> 252600.8 | D40: ='Raw_Gross Domestic Product '!AN3 -> 20656.5 | E40: =((D40-D39)/D39)*100 -> 5.3252839 | F40: ='Raw_Personal Income and Its Dis'!AO3 -> 17528.2 | G40: =Raw_Unemployment!B40 -> 46.7 | H40: =B39 -> 796106 | I40: =E39 -> 4.2924982 | K40: =B40 -> 631502 | L40: =G40 -> 46.7 | M40: =H40 -> 796106 | O40: =G40 -> 46.7 | P40: =E40 -> 5.3252839 | Q40: =B40 -> 631502 | R40: =H40 -> 796106 | T40: =F40 -> 17528.2 | U40: =B40 -> 631502 | V40: =D40 -> 20656.5 | W40: =G40 -> 46.7
...

Sheet Analysis
B1: Mean | C1: Median | D1: Std. Dev | E1: Min | F1: Max | G1: Count | J1: ='Master Dataset'!B1 -> Net Immigration | K1: ='Master Dataset'!D1 -> GDP Nominal | L1: ='Master Dataset'!E1 -> GDP Growth Rate | M1: ='Master Dataset'!F1 -> Personal Income | N1: ='Master Dataset'!G1 -> Unemployment Rate
A2: Net Immigration | B2: =AVERAGE('Master Dataset'!B2:B43) -> -38371.262 | C2: =MEDIAN('Master Dataset'!B2:B43) -> -89065.5 | D2: =_xlfn.STDEV.S('Master Dataset'!B2:B43) -> 525505.05 | E2: =MIN('Master Dataset'!B2:B43) -> -1027905 | F2: =MAX('Master Dataset'!B2:B43) -> 845690 | G2: =COUNT('Master Dataset'!B2:B43) -> 42 | J2: ='Master Dataset'!B2 -> -5813 | K2: ='Master Dataset'!D2 -> 2857.3 | M2: ='Master Dataset'!F2 -> 2324.5 | N2: ='Master Dataset'!G2 -> 86.1
A3: GDP growth rate | B3: =AVERAGE('Master Dataset'!E2:E43) -> 5.3313412 | C3: =MEDIAN('Master Dataset'!E2:E43) -> 5.3252839 | D3: =_xlfn.STDEV.S('Master Dataset'!E2:E43) -> 2.6750046 | E3: =MIN('Master Dataset'!E2:E43) -> -1.9756396 | F3: =MAX('Master Dataset'!E2:E43) -> 12.238827 | G3: =COUNT('Master Dataset'!E2:E43) -> 41 | J3: ='Master Dataset'!B3 -> -86988 | K3: ='Master Dataset'!D3 -> 3207 | L3: ='Master Dataset'!E3 -> 12.238827 | M3: ='Master Dataset'!F3 -> 2603.2 | N3: ='Master Dataset'!G3 -> 91.4
A4: Unemployment Rate | B4: =AVERAGE('Master Dataset'!G2:G43) -> 74.695238 | C4: =MEDIAN('Master Dataset'!G2:G43) -> 69.5 | D4: =_xlfn.STDEV.S('Master Dataset'!G2:G43) -> 19.971369 | E4: =MIN('Master Dataset'!G2:G43) -> 44.1 | F4: =MAX('Master Dataset'!G2:G43) -> 116.5 | G4: =COUNT('Master Dataset'!G2:G43) -> 42 | J4: ='Master Dataset'!B4 -> -196068 | K4: ='Master Dataset'!D4 -> 3343.8 | L4: ='Master Dataset'!E4 -> 4.2656688 | M4: ='Master Dataset'!F4 -> 2789.5 | N4: ='Master Dataset'!G4 -> 116.5
A5: Personal Income | B5: =AVERAGE('Master Dataset'!F2:F43) -> 9402.6524 | C5: =MEDIAN('Master Dataset'!F2:F43) -> 8807.2 | D5: =_xlfn.STDEV.S('Master Dataset'!F2:F43) -> 5242.6848 | E5: =MIN('Master Dataset'!F2:F43) -> 2324.5 | F5: =MAX('Master Dataset'!F2:F43) -> 21498.9 | G5: =COUNT('Master Dataset'!F2:F43) -> 42 | J5: ='Master Dataset'!B5 -> -339541 | K5: ='Master Dataset'!D5 -> 3634 | L5: ='Master Dataset'!E5 -> 8.6787487 | M5: ='Master Dataset'!F5 -> 2981.7 | N5: ='Master Dataset'!G5 -> 115.2
J6: ='Master Dataset'!B6 -> -316325 | K6: ='Master Dataset'!D6 -> 4037.6 | L6: ='Master Dataset'!E6 -> 11.106219 | M6: ='Master Dataset'!F6 -> 3288.7 | N6: ='Master Dataset'!G6 -> 90.1
J7: ='Master Dataset'!B7 -> -428548 | K7: ='Master Dataset'!D7 -> 4339 | L7: ='Master Dataset'!E7 -> 7.4648306 | M7: ='Master Dataset'!F7 -> 3522.9 | N7: ='Master Dataset'!G7 -> 86.3
J8: ='Master Dataset'!B8 -> -948739 | K8: ='Master Dataset'!D8 -> 4579.6 | L8: ='Master Dataset'!E8 -> 5.5450565 | M8: ='Master Dataset'!F8 -> 3731.2 | N8: ='Master Dataset'!G8 -> 84
J9: ='Master Dataset'!B9 -> -451122 | K9: ='Master Dataset'!D9 -> 4855.2 | L9: ='Master Dataset'!E9 -> 6.0179928 | M9: ='Master Dataset'!F9 -> 3946.8 | N9: ='Master Dataset'!G9 -> 74.1
B10: -5813 | C10: -2325.2 | D10: 2857.3 | F10: 2324.5 | G10: 86.1 | J10: ='Master Dataset'!B10 -> -219790 | K10: ='Master Dataset'!D10 -> 5236.4 | L10: ='Master Dataset'!E10 -> 7.8513758 | M10: ='Master Dataset'!F10 -> 4280 | N10: ='Master Dataset'!G10 -> 65.9
A11: -5813 | B11: 1 | J11: ='Master Dataset'!B11 -> 331925 | K11: ='Master Dataset'!D11 -> 5641.6 | L11: ='Master Dataset'!E11 -> 7.7381407 | M11: ='Master Dataset'!F11 -> 4621 | N11: ='Master Dataset'!G11 -> 63.1
A12: -2325.2 | B12: 1 | C12: 1 | J12: ='Master Dataset'!B12 -> 605366 | K12: ='Master Dataset'!D12 -> 5963.1 | L12: ='Master Dataset'!E12 -> 5.6987379 | M12: ='Master Dataset'!F12 -> 4913.3 | N12: ='Master Dataset'!G12 -> 67.4
A13: 2857.3 | B13: 0.58413019 | C13: 0.58413019 | D13: 1 | J13: ='Master Dataset'!B13 -> 845690 | K13: ='Master Dataset'!D13 -> 6158.1 | L13: ='Master Dataset'!E13 -> 3.2701112 | M13: ='Master Dataset'!F13 -> 5089.9 | N13: ='Master Dataset'!G13 -> 82.2
B14: -0.2935209 | C14: -0.2935209 | D14: -0.42512003 | E14: 1 | J14: ='Master Dataset'!B14 -> -60507 | K14: ='Master Dataset'!D14 -> 6520.3 | L14: ='Master Dataset'!E14 -> 5.8816843 | M14: ='Master Dataset'!F14 -> 5417.5 | N14: ='Master Dataset'!G14 -> 89.9
A15: 2324.5 | B15: 0.583286 | C15: 0.583286 | D15: 0.9980378 | E15: -0.41624809 | F15: 1 | J15: ='Master Dataset'!B15 -> -267855 | K15: ='Master Dataset'!D15 -> 6858.6 | L15: ='Master Dataset'!E15 -> 5.1884116 | M15: ='Master Dataset'!F15 -> 5652.9 | N15: ='Master Dataset'!G15 -> 82.9
A16: 86.1 | B16: 0.097272345 | C16: 0.097272345 | D16: -0.25610821 | E16: -0.13208492 | F16: -0.239667 | G16: 1 | J16: ='Master Dataset'!B16 -> -159108 | K16: ='Master Dataset'!D16 -> 7287.2 | L16: ='Master Dataset'!E16 -> 6.2490887 | M16: ='Master Dataset'!F16 -> 5940.9 | N16: ='Master Dataset'!G16 -> 73.2
J17: ='Master Dataset'!B17 -> -545538 | K17: ='Master Dataset'!D17 -> 7639.7 | L17: ='Master Dataset'!E17 -> 4.8372489 | M17: ='Master Dataset'!F17 -> 6283.4 | N17: ='Master Dataset'!G17 -> 67.1
J18: ='Master Dataset'!B18 -> -652127 | K18: ='Master Dataset'!D18 -> 8073.1 | L18: ='Master Dataset'!E18 -> 5.6729976 | M18: ='Master Dataset'!F18 -> 6666.2 | N18: ='Master Dataset'!G18 -> 64.9
J19: ='Master Dataset'!B19 -> -687616 | K19: ='Master Dataset'!D19 -> 8577.6 | L19: ='Master Dataset'!E19 -> 6.2491484 | M19: ='Master Dataset'!F19 -> 7074 | N19: ='Master Dataset'!G19 -> 59.3
A20: Correlation of Immigration and Economic Variables (1980–2021) | J20: ='Master Dataset'!B20 -> -1015022 | K20: ='Master Dataset'!D20 -> 9062.8 | L20: ='Master Dataset'!E20 -> 5.6565939 | M20: ='Master Dataset'!F20 -> 7588.4 | N20: ='Master Dataset'!G20 -> 54
B21: Net Immigration | C21: GDP Nominal | D21: GDP Growth Rate | E21: Personal Income | F21: Unemployment Rate | J21: ='Master Dataset'!B21 -> -1027905 | K21: ='Master Dataset'!D21 -> 9631.2 | L21: ='Master Dataset'!E21 -> 6.2717924 | M21: ='Master Dataset'!F21 -> 7978.6 | N21: ='Master Dataset'!G21 -> 50.6
A22: Net Immigration | B22: 1 | J22: ='Master Dataset'!B22 -> -951176 | K22: ='Master Dataset'!D22 -> 10251 | L22: ='Master Dataset'!E22 -> 6.4353352 | M22: ='Master Dataset'!F22 -> 8621.3 | N22: ='Master Dataset'!G22 -> 47.6
A23: GDP Nominal | B23: 0.5676538 | C23: 1 | J23: ='Master Dataset'!B23 -> -410575 | K23: ='Master Dataset'!D23 -> 10581.9 | L23: ='Master Dataset'!E23 -> 3.2279778 | M23: ='Master Dataset'!F23 -> 8993.1 | N23: ='Master Dataset'!G23 -> 56.9
A24: GDP Growth Rate | B24: -0.2935209 | C24: -0.42512003 | D24: 1 | J24: ='Master Dataset'!B24 -> -91143 | K24: ='Master Dataset'!D24 -> 10929.1 | L24: ='Master Dataset'!E24 -> 3.2810743 | M24: ='Master Dataset'!F24 -> 9150 | N24: ='Master Dataset'!G24 -> 69.4
A25: Personal Income | B25: 0.56773192 | C25: 0.99810792 | D25: -0.41624809 | E25: 1 | J25: ='Master Dataset'!B25 -> -424564 | K25: ='Master Dataset'!D25 -> 11456.5 | L25: ='Master Dataset'!E25 -> 4.825649 | M25: ='Master Dataset'!F25 -> 9481.8 | N25: ='Master Dataset'!G25 -> 71.9
A26: Unemployment Rate | B26: 0.097754597 | C26: -0.26866807 | D26: -0.13208492 | E26: -0.25245319 | F26: 1 | J26: ='Master Dataset'!B26 -> -396518 | K26: ='Master Dataset'!D26 -> 12217.2 | L26: ='Master Dataset'!E26 -> 6.6398987 | M26: ='Master Dataset'!F26 -> 10015.9 | N26: ='Master Dataset'!G26 -> 66.5
J27: ='Master Dataset'!B27 -> -167356 | K27: ='Master Dataset'!D27 -> 13039.2 | L27: ='Master Dataset'!E27 -> 6.7282192 | M27: ='Master Dataset'!F27 -> 10546.1 | N27: ='Master Dataset'!G27 -> 61
J28: ='Master Dataset'!B28 -> -17132 | K28: ='Master Dataset'!D28 -> 13815.6 | L28: ='Master Dataset'!E28 -> 5.954353 | M28: ='Master Dataset'!F28 -> 11302 | N28: ='Master Dataset'!G28 -> 55.3
J29: ='Master Dataset'!B29 -> -110139 | K29: ='Master Dataset'!D29 -> 14474.2 | L29: ='Master Dataset'!E29 -> 4.7670749 | M29: ='Master Dataset'!F29 -> 11932.1 | N29: ='Master Dataset'!G29 -> 55.4
J30: ='Master Dataset'!B30 -> -3825 | K30: ='Master Dataset'!D30 -> 14769.9 | L30: ='Master Dataset'!E30 -> 2.0429454 | M30: ='Master Dataset'!F30 -> 12425.7 | N30: ='Master Dataset'!G30 -> 69.6
J31: ='Master Dataset'!B31 -> 243114 | K31: ='Master Dataset'!D31 -> 14478.1 | L31: ='Master Dataset'!E31 -> -1.9756396 | M31: ='Master Dataset'!F31 -> 12065.7 | N31: ='Master Dataset'!G31 -> 111.4
J32: ='Master Dataset'!B32 -> 261671 | K32: ='Master Dataset'!D32 -> 15049 | L32: ='Master Dataset'!E32 -> 3.943197 | M32: ='Master Dataset'!F32 -> 12556.6 | N32: ='Master Dataset'!G32 -> 115.3
J33: ='Master Dataset'!B33 -> 405965 | K33: ='Master Dataset'!D33 -> 15599.7 | L33: ='Master Dataset'!E33 -> 3.6593794 | M33: ='Master Dataset'!F33 -> 13309.6 | N33: ='Master Dataset'!G33 -> 107.2
J34: ='Master Dataset'!B34 -> 443126 | K34: ='Master Dataset'!D34 -> 16254 | L34: ='Master Dataset'!E34 -> 4.1943114 | M34: ='Master Dataset'!F34 -> 13917.8 | N34: ='Master Dataset'!G34 -> 96.9
J35: ='Master Dataset'!B35 -> 449288 | K35: ='Master Dataset'!D35 -> 16880.7 | L35: ='Master Dataset'!E35 -> 3.8556663 | M35: ='Master Dataset'!F35 -> 14068.8 | N35: ='Master Dataset'!G35 -> 88.3
J36: ='Master Dataset'!B36 -> 517631 | K36: ='Master Dataset'!D36 -> 17608.1 | L36: ='Master Dataset'!E36 -> 4.309063 | M36: ='Master Dataset'!F36 -> 14784.1 | N36: ='Master Dataset'!G36 -> 73.9
J37: ='Master Dataset'!B37 -> 667012 | K37: ='Master Dataset'!D37 -> 18295 | L37: ='Master Dataset'!E37 -> 3.9010455 | M37: ='Master Dataset'!F37 -> 15473.7 | N37: ='Master Dataset'!G37 -> 63.3
J38: ='Master Dataset'!B38 -> 829752 | K38: ='Master Dataset'!D38 -> 18804.9 | L38: ='Master Dataset'!E38 -> 2.7871003 | M38: ='Master Dataset'!F38 -> 15887.7 | N38: ='Master Dataset'!G38 -> 58.5
... J43: ='Master Dataset'!B43 -> 484038 | K43: ='Master Dataset'!D43 -> 23725.6 | L43: ='Master Dataset'!E43 -> 10.995401 | M43: ='Master Dataset'!F43 -> 21498.9 | N43: ='Master Dataset'!G43 -> 64.3

Sheet Result 1
A1: SUMMARY OUTPUT | B1: MODEL 1: Impact of Immigration on GDP Growth
A3: Regression Statistics
A4: Multiple R | B4: 0.3101011
A5: R Square | B5: 0.096162692
A6: Adjusted R Square | B6: 0.024807115
A7: Standard Error | B7: 2.7327449
A8: Observations | B8: 42
A10: ANOVA
B11: df | C11: SS | D11: MS | E11: F | F11: Significance F
A12: Regression | B12: 3 | C12: 30.192435 | D12: 10.064145 | E12: 1.3476549 | F12: 0.27340928
A13: Residual | B13: 38 | C13: 283.78 | D13: 7.4678949
A14: Total | B14: 41 | C14: 313.97244
B16: Coefficients | C16: Standard Error | D16: t Stat | E16: P-value | F16: Lower 95% | G16: Upper 95% | H16: Lower 95.0% | I16: Upper 95.0%
A17: Intercept | B17: 6.4154939 | C17: 1.6984086 | D17: 3.7773559 | E17: 0.00054339677 | F17: 2.9772453 | G17: 9.8537424 | H17: 2.9772453 | I17: 9.8537424
A18: Net Immigration | B18: -1.2754859e-06 | C18: 1.6204676e-06 | D18: -0.78710982 | E18: 0.43609947 | F18: -4.5559511e-06 | G18: 2.0049792e-06 | H18: -4.5559511e-06 | I18: 2.0049792e-06
A19: Unemployment Rate | B19: -0.016988417 | C19: 0.021901711 | D19: -0.77566621 | E19: 0.44274692 | F19: -0.061326114 | G19: 0.027349279 | H19: -0.061326114 | I19: 0.027349279
A20: Immigration Lag1 | B20: -1.7882237e-07 | C20: 1.6609667e-06 | D20: -0.10766162 | E20: 0.91483056 | F20: -3.5412738e-06 | G20: 3.183629e-06 | H20: -3.5412738e-06 | I20: 3.183629e-06
A24: RESIDUAL OUTPUT
A26: Observation | B26: Predicted GDP Growth Rate | C26: Residuals
A27: 1 | B27: 4.9602055 | C27: -4.9602055
A28: 2 | B28: 4.974744 | C28: 7.2640829
A29: 3 | B29: 4.7019806 | C29: -0.43631176
A30: 4 | B30: 4.9265693 | C30: 3.7521794
A31: 5 | B31: 5.3490231 | C31: 5.757196
A32: 6 | B32: 5.5525664 | C32: 1.9122642
A33: 7 | B33: 6.275204 | C33: -0.73014756
A34: 8 | B34: 5.9017077 | C34: 0.11628518
A35: 9 | B35: 5.6569669 | C35: 2.1944089
A36: 10 | B36: 4.9594624 | C36: 2.7786783
A37: 11 | B37: 4.4389831 | C37: 1.2597549
A38: 12 | B38: 3.8321273 | C38: -0.56201608
... A68: 42 | B68: 4.6496248 | C68: 6.3457765

Sheet Result 2
A2: SUMMARY OUTPUT | B2: MODEL 2: Immigration Impact on Unemployment
A4: Regression Statistics
A5: Multiple R | B5: 0.2506513
A6: R Square | B6: 0.062826072
A7: Adjusted R Square | B7: -0.011161343
A8: Standard Error | B8: 20.082514
A9: Observations | B9: 42
A11: ANOVA
B12: df | C12: SS | D12: MS | E12: F | F12: Significance F
A13: Regression | B13: 3 | C13: 1027.3997 | D13: 342.46657 | E13: 0.84914538 | F13: 0.47572504
A14: Residual | B14: 38 | C14: 15325.679 | D14: 403.30735
A15: Total | B15: 41 | C15: 16353.079
B17: Coefficients | C17: Standard Error | D17: t Stat | E17: P-value | F17: Lower 95% | G17: Upper 95% | H17: Lower 95.0% | I17: Upper 95.0%
A18: Intercept | B18: 79.81005 | C18: 6.8305221 | D18: 11.684326 | E18: 3.8036925e-14 | F18: 65.982381 | G18: 93.637719 | H18: 65.982381 | I18: 93.637719
A19: GDP Growth Rate | B19: -0.91746787 | C19: 1.1828127 | D19: -0.77566621 | E19: 0.44274692 | F19: -3.3119471 | G19: 1.4770113 | H19: -3.3119471 | I19: 1.4770113
A20: Net Immigration | B20: -1.005021e-05 | C20: 1.1894027e-05 | D20: -0.84497965 | E20: 0.40341113 | F20: -3.4128409e-05 | G20: 1.4027988e-05 | H20: -3.4128409e-05 | I20: 1.4027988e-05
A21: Immigration Lag1 | B21: 1.45418e-05 | C21: 1.197796e-05 | D21: 1.2140465 | E21: 0.23222144 | F21: -9.7063122e-06 | G21: 3.8789913e-05 | H21: -9.7063122e-06 | I21: 3.8789913e-05
A25: RESIDUAL OUTPUT
A27: Observation | B27: Predicted Unemployment Rate | C27: Residuals
A28: 1 | B28: 79.868472 | C28: 6.231528
A29: 2 | B29: 69.371036 | C29: 22.028964
A30: 3 | B30: 76.601999 | C30: 39.898001
A31: 4 | B31: 72.408854 | C31: 42.791146
A32: 5 | B32: 67.862046 | C32: 22.237954
A33: 6 | B33: 72.66837 | C33: 13.63163
A34: 7 | B34: 78.025806 | C34: 5.9741939
A35: 8 | B35: 65.026233 | C35: 9.0737672
A36: 9 | B36: 68.255475 | C36: -2.3554747
A37: 10 | B37: 66.178496 | C37: -3.0784962
A38: 11 | B38: 73.324372 | C38: -5.9243725
A39: 12 | B39: 77.113577 | C39: 5.0864228
... A69: 42 | B69: 69.421936 | C69: -5.1219356

Sheet Result 3
A1: SUMMARY OUTPUT | B1: MODEL 3: Immigration Impact on Personal Income
A3: Regression Statistics
A4: Multiple R | B4: 0.99824891
A5: R Square | B5: 0.99650089
A6: Adjusted R Square | B6: 0.99622465
A7: Standard Error | B7: 322.13093
A8: Observations | B8: 42
A10: ANOVA
B11: df | C11: SS | D11: MS | E11: F | F11: Significance F
A12: Regression | B12: 3 | C12: 1.1229723e+09 | D12: 3.743241e+08 | E12: 3607.3056 | F12: 1.0832231e-46
A13: Residual | B13: 38 | C13: 3943196.8 | D13: 103768.34
A14: Total | B14: 41 | C14: 1.1269155e+09
B16: Coefficients | C16: Standard Error | D16: t Stat | E16: P-value | F16: Lower 95% | G16: Upper 95% | H16: Lower 95.0% | I16: Upper 95.0%
A17: Intercept | B17: -817.0173 | C17: 286.25944 | D17: -2.8541147 | E17: 0.0069509568 | F17: -1396.5192 | G17: -237.51535 | H17: -1396.5192 | I17: -237.51535
A18: Net Immigration | B18: -5.0423896e-05 | C18: 0.00012254759 | D18: -0.41146379 | E18: 0.68304405 | F18: -0.00029850852 | G18: 0.00019766073 | H18: -0.00029850852 | I18: 0.00019766073
A19: GDP Nominal | B19: 0.88305796 | C19: 0.011141656 | D19: 79.257338 | E19: 8.1857315e-44 | F19: 0.86050286 | G19: 0.90561307 | H19: 0.86050286 | I19: 0.90561307
A20: Unemployment Rate | B20: 4.8017817 | C20: 2.756027 | D20: 1.742284 | E20: 0.089548122 | F20: -0.77750319 | G20: 10.381067 | H20: -0.77750319 | I20: 10.381067
A24: RESIDUAL OUTPUT
A26: Observation | B26: Predicted Personal Income | C26: Residuals
A27: 1 | B27: 2119.8707 | C27: 204.62926
A28: 2 | B28: 2458.2187 | C28: 144.98129
A29: 3 | B29: 2705.046 | C29: 84.454003
A30: 4 | B30: 2962.3016 | C30: 19.398431
A31: 5 | B31: 3197.0084 | C31: 91.691598
A32: 6 | B32: 3450.574 | C32: 72.325978
A33: 7 | B33: 3678.2237 | C33: 52.976273
A34: 8 | B34: 3848.9651 | C34: 97.834925
A35: 9 | B35: 4134.5475 | C35: 145.4525
A36: 10 | B36: 4451.098 | C36: 169.90202
A37: 11 | B37: 4741.8608 | C37: 171.43919
A38: 12 | B38: 4973.0054 | C38: 116.89459
... A68: 42 | B68: 20418.41 | C68: 1080.4898

Sheet Training Data
A1: Year | B1: Net Immigration | C1: Immigration Rate | D1: GDP Nominal | E1: GDP Growth Rate | F1: Personal Income | G1: Unemployment Rate | H1: Immigration Lag1 | I1: GDP lag1 | K1: Net Immigration | L1: =G1 -> Unemployment Rate | M1: =H1 -> Immigration Lag1 | Y1: =E1 -> GDP Growth Rate | Z1: =B1 -> Net Immigration | AA1: =H1 -> Immigration Lag1 | AD1: =B1 -> Net Immigration | AE1: =D1 -> GDP Nominal | AF1: =G1 -> Unemployment Rate
A2: 1980 | B2: =VLOOKUP(A2,'Raw_Imigration data'!A:G, 7, FALSE) -> -5813 | C2: =VLOOKUP(A2,'Raw_Imigration data'!A:H, 8, FALSE) -> -2325.2 | D2: ='Raw_Gross Domestic Product '!B3 -> 2857.3 | F2: ='Raw_Personal Income and Its Dis'!C3 -> 2324.5 | G2: =Raw_Unemployment!B2 -> 86.1 | K2: =B2 -> -5813 | L2: =G2 -> 86.1 | M2: =H2 -> 0 | O2: SUMMARY OUTPUT | P2: Model 1 | Y2: =E2 -> 0 | Z2: =B2 -> -5813 | AA2: =H2 -> 0 | AD2: =B2 -> -5813 | AE2: =D2 -> 2857.3 | AF2: =G2 -> 86.1
A3: 1981 | B3: =VLOOKUP(A3,'Raw_Imigration data'!A:G, 7, FALSE) -> -86988 | C3: =VLOOKUP(A3,'Raw_Imigration data'!A:H, 8, FALSE) -> -34795.2 | D3: ='Raw_Gross Domestic Product '!C3 -> 3207 | E3: =((D3-D2)/D2)*100 -> 12.238827 | F3: ='Raw_Personal Income and Its Dis'!D3 -> 2603.2 | G3: =Raw_Unemployment!B3 -> 91.4 | H3: =B2 -> -5813 | K3: =B3 -> -86988 | L3: =G3 -> 91.4 | M3: =H3 -> -5813 | Y3: =E3 -> 12.238827 | Z3: =B3 -> -86988 | AA3: =H3 -> -5813 | AD3: =B3 -> -86988 | AE3: =D3 -> 3207 | AF3: =G3 -> 91.4
A4: 1982 | B4: =VLOOKUP(A4,'Raw_Imigration data'!A:G, 7, FALSE) -> -196068 | C4: =VLOOKUP(A4,'Raw_Imigration data'!A:H, 8, FALSE) -> -78427.2 | D4: ='Raw_Gross Domestic Product '!D3 -> 3343.8 | E4: =((D4-D3)/D3)*100 -> 4.2656688 | F4: ='Raw_Personal Income and Its Dis'!E3 -> 2789.5 | G4: =Raw_Unemployment!B4 -> 116.5 | H4: =B3 -> -86988 | I4: =E3 -> 12.238827 | K4: =B4 -> -196068 | L4: =G4 -> 116.5 | M4: =H4 -> -86988 | O4: Regression Statistics | Y4: =E4 -> 4.2656688 | Z4: =B4 -> -196068 | AA4: =H4 -> -86988 | AD4: =B4 -> -196068 | AE4: =D4 -> 3343.8 | AF4: =G4 -> 116.5
A5: 1983 | B5: =VLOOKUP(A5,'Raw_Imigration data'!A:G, 7, FALSE) -> -339541 | C5: =VLOOKUP(A5,'Raw_Imigration data'!A:H, 8, FALSE) -> -135816.4 | D5: ='Raw_Gross Domestic Product '!E3 -> 3634 | E5: =((D5-D4)/D4)*100 -> 8.6787487 | F5: ='Raw_Personal Income and Its Dis'!F3 -> 2981.7 | G5: =Raw_Unemployment!B5 -> 115.2 | H5: =B4 -> -196068 | I5: =E4 -> 4.2656688 | K5: =B5 -> -339541 | L5: =G5 -> 115.2 | M5: =H5 -> -196068 | O5: Multiple R | P5: 0.45658094 | Y5: =E5 -> 8.6787487 | Z5: =B5 -> -339541 | AA5: =H5 -> -196068 | AD5: =B5 -> -339541 | AE5: =D5 -> 3634 | AF5: =G5 -> 115.2
A6: 1984 | B6: =VLOOKUP(A6,'Raw_Imigration data'!A:G, 7, FALSE) -> -316325 | C6: =VLOOKUP(A6,'Raw_Imigration data'!A:H, 8, FALSE) -> -126530 | D6: ='Raw_Gross Domestic Product '!F3 -> 4037.6 | E6: =((D6-D5)/D5)*100 -> 11.106219 | F6: ='Raw_Personal Income and Its Dis'!G3 -> 3288.7 | G6: =Raw_Unemployment!B6 -> 90.1 | H6: =B5 -> -339541 | I6: =E5 -> 8.6787487 | K6: =B6 -> -316325 | L6: =G6 -> 90.1 | M6: =H6 -> -339541 | O6: R Square | P6: 0.20846616 | Y6: =E6 -> 11.106219 | Z6: =B6 -> -316325 | AA6: =H6 -> -339541 | AD6: =B6 -> -316325 | AE6: =D6 -> 4037.6 | AF6: =G6 -> 90.1
A7: 1985 | B7: =VLOOKUP(A7,'Raw_Imigration data'!A:G, 7, FALSE) -> -428548 | C7: =VLOOKUP(A7,'Raw_Imigration data'!A:H, 8, FALSE) -> -171419.2 | D7: ='Raw_Gross Domestic Product '!G3 -> 4339 | E7: =((D7-D6)/D6)*100 -> 7.4648306 | F7: ='Raw_Personal Income and Its Dis'!H3 -> 3522.9 | G7: =Raw_Unemployment!B7 -> 86.3 | H7: =B6 -> -316325 | I7: =E6 -> 11.106219 | K7: =B7 -> -428548 | L7: =G7 -> 86.3 | M7: =H7 -> -316325 | O7: Adjusted R Square | P7: 0.13425986 | Y7: =E7 -> 7.4648306 | Z7: =B7 -> -428548 | AA7: =H7 -> -316325 | AD7: =B7 -> -428548 | AE7: =D7 -> 4339 | AF7: =G7 -> 86.3
A8: 1986 | B8: =VLOOKUP(A8,'Raw_Imigration data'!A:G, 7, FALSE) -> -948739 | C8: =VLOOKUP(A8,'Raw_Imigration data'!A:H, 8, FALSE) -> -379495.6 | D8: ='Raw_Gross Domestic Product '!H3 -> 4579.6 | E8: =((D8-D7)/D7)*100 -> 5.5450565 | F8: ='Raw_Personal Income and Its Dis'!I3 -> 3731.2 | G8: =Raw_Unemployment!B8 -> 84 | H8: =B7 -> -428548 | I8: =E7 -> 7.4648306 | K8: =B8 -> -948739 | L8: =G8 -> 84 | M8: =H8 -> -428548 | O8: Standard Error | P8: 6.3510312 | Y8: =E8 -> 5.5450565 | Z8: =B8 -> -948739 | AA8: =H8 -> -428548 | AD8: =B8 -> -948739 | AE8: =D8 -> 4579.6 | AF8: =G8 -> 84
A9: 1987 | B9: =VLOOKUP(A9,'Raw_Imigration data'!A:G, 7, FALSE) -> -451122 | C9: =VLOOKUP(A9,'Raw_Imigration data'!A:H, 8, FALSE) -> -180448.8 | D9: ='Raw_Gross Domestic Product '!I3 -> 4855.2 | E9: =((D9-D8)/D8)*100 -> 6.0179928 | F9: ='Raw_Personal Income and Its Dis'!J3 -> 3946.8 | G9: =Raw_Unemployment!B9 -> 74.1 | H9: =B8 -> -948739 | I9: =E8 -> 5.5450565 | K9: =B9 -> -451122 | L9: =G9 -> 74.1 | M9: =H9 -> -948739 | O9: Observations | P9: 36 | Y9: =E9 -> 6.0179928 | Z9: =B9 -> -451122 | AA9: =H9 -> -948739 | AD9: =B9 -> -451122 | AE9: =D9 -> 4855.2 | AF9: =G9 -> 74.1
A10: 1988 | B10: =VLOOKUP(A10,'Raw_Imigration data'!A:G, 7, FALSE) -> -219790 | C10: =VLOOKUP(A10,'Raw_Imigration data'!A:H, 8, FALSE) -> -87916 | D10: ='Raw_Gross Domestic Product '!J3 -> 5236.4 | E10: =((D10-D9)/D9)*100 -> 7.8513758 | F10: ='Raw_Personal Income and Its Dis'!K3 -> 4280 | G10: =Raw_Unemployment!B10 -> 65.9 | H10: =B9 -> -451122 | I10: =E9 -> 6.0179928 | K10: =B10 -> -219790 | L10: =G10 -> 65.9 | M10: =H10 -> -451122 | Y10: =E10 -> 7.8513758 | Z10: =B10 -> -219790 | AA10: =H10 -> -451122 | AD10: =B10 -> -219790 | AE10: =D10 -> 5236.4 | AF10: =G10 -> 65.9
A11: 1989 | B11: =VLOOKUP(A11,'Raw_Imigration data'!A:G, 7, FALSE) -> 331925 | C11: =VLOOKUP(A11,'Raw_Imigration data'!A:H, 8, FALSE) -> 132770 | D11: ='Raw_Gross Domestic Product '!K3 -> 5641.6 | E11: =((D11-D10)/D10)*100 -> 7.7381407 | F11: ='Raw_Personal Income and Its Dis'!L3 -> 4621 | G11: =Raw_Unemployment!B11 -> 63.1 | H11: =B10 -> -219790 | I11: =E10 -> 7.8513758 | K11: =B11 -> 331925 | L11: =G11 -> 63.1 | M11: =H11 -> -219790 | O11: ANOVA | Y11: =E11 -> 7.7381407 | Z11: =B11 -> 331925 | AA11: =H11 -> -219790 | AD11: =B11 -> 331925 | AE11: =D11 -> 5641.6 | AF11: =G11 -> 63.1
A12: 1990 | B12: =VLOOKUP(A12,'Raw_Imigration data'!A:G, 7, FALSE) -> 605366 | C12: =VLOOKUP(A12,'Raw_Imigration data'!A:H, 8, FALSE) -> 242146.4 | D12: ='Raw_Gross Domestic Product '!L3 -> 5963.1 | E12: =((D12-D11)/D11)*100 -> 5.6987379 | F12: ='Raw_Personal Income and Its Dis'!M3 -> 4913.3 | G12: =Raw_Unemployment!B12 -> 67.4 | H12: =B11 -> 331925 | I12: =E11 -> 7.7381407 | K12: =B12 -> 605366 | L12: =G12 -> 67.4 | M12: =H12 -> 331925 | P12: df | Q12: SS | R12: MS | S12: F | T12: Significance F | Y12: =E12 -> 5.6987379 | Z12: =B12 -> 605366 | AA12: =H12 -> 331925 | AD12: =B12 -> 605366 | AE12: =D12 -> 5963.1 | AF12: =G12 -> 67.4
A13: 1991 | B13: =VLOOKUP(A13,'Raw_Imigration data'!A:G, 7, FALSE) -> 845690 | C13: =VLOOKUP(A13,'Raw_Imigration data'!A:H, 8, FALSE) -> 338276 | D13: ='Raw_Gross Domestic Product '!M3 -> 6158.1 | E13: =((D13-D12)/D12)*100 -> 3.2701112 | F13: ='Raw_Personal Income and Its Dis'!N3 -> 5089.9 | G13: =Raw_Unemployment!B13 -> 82.2 | H13: =B12 -> 605366 | I13: =E12 -> 5.6987379 | K13: =B13 -> 845690 | L13: =G13 -> 82.2 | M13: =H13 -> 605366 | O13: Regression | P13: 3 | Q13: 339.94178 | R13: 113.31393 | S13: 2.8092785 | T13: 0.055187726 | Y13: =E13 -> 3.2701112 | Z13: =B13 -> 845690 | AA13: =H13 -> 605366 | AD13: =B13 -> 845690 | AE13: =D13 -> 6158.1 | AF13: =G13 -> 82.2
A14: 1992 | B14: =VLOOKUP(A14,'Raw_Imigration data'!A:G, 7, FALSE) -> -60507 | C14: =VLOOKUP(A14,'Raw_Imigration data'!A:H, 8, FALSE) -> -24202.8 | D14: ='Raw_Gross Domestic Product '!N3 -> 6520.3 | E14: =((D14-D13)/D13)*100 -> 5.8816843 | F14: ='Raw_Personal Income and Its Dis'!O3 -> 5417.5 | G14: =Raw_Unemployment!B14 -> 89.9 | H14: =B13 -> 845690 | I14: =E13 -> 3.2701112 | K14: =B14 -> -60507 | L14: =G14 -> 89.9 | M14: =H14 -> 845690 | O14: Residual | P14: 32 | Q14: 1290.7391 | R14: 40.335597 | Y14: =E14 -> 5.8816843 | Z14: =B14 -> -60507 | AA14: =H14 -> 845690 | AD14: =B14 -> -60507 | AE14: =D14 -> 6520.3 | AF14: =G14 -> 89.9
A15: 1993 | B15: =VLOOKUP(A15,'Raw_Imigration data'!A:G, 7, FALSE) -> -267855 | C15: =VLOOKUP(A15,'Raw_Imigration data'!A:H, 8, FALSE) -> -107142 | D15: ='Raw_Gross Domestic Product '!O3 -> 6858.6 | E15: =((D15-D14)/D14)*100 -> 5.1884116 | F15: ='Raw_Personal Income and Its Dis'!P3 -> 5652.9 | G15: =Raw_Unemployment!B15 -> 82.9 | H15: =B14 -> -60507 | I15: =E14 -> 5.8816843 | K15: =B15 -> -267855 | L15: =G15 -> 82.9 | M15: =H15 -> -60507 | O15: Total | P15: 35 | Q15: 1630.6809 | Y15: =E15 -> 5.1884116 | Z15: =B15 -> -267855 | AA15: =H15 -> -60507 | AD15: =B15 -> -267855 | AE15: =D15 -> 6858.6 | AF15: =G15 -> 82.9
A16: 1994 | B16: =VLOOKUP(A16,'Raw_Imigration data'!A:G, 7, FALSE) -> -159108 | C16: =VLOOKUP(A16,'Raw_Imigration data'!A:H, 8, FALSE) -> -63643.2 | D16: ='Raw_Gross Domestic Product '!P3 -> 7287.2 | E16: =((D16-D15)/D15)*100 -> 6.2490887 | F16: ='Raw_Personal Income and Its Dis'!Q3 -> 5940.9 | G16: =Raw_Unemployment!B16 -> 73.2 | H16: =B15 -> -267855 | I16: =E15 -> 5.1884116 | K16: =B16 -> -159108 | L16: =G16 -> 73.2 | M16: =H16 -> -267855 | Y16: =E16 -> 6.2490887 | Z16: =B16 -> -159108 | AA16: =H16 -> -267855 | AD16: =B16 -> -159108 | AE16: =D16 -> 7287.2 | AF16: =G16 -> 73.2
A17: 1995 | B17: =VLOOKUP(A17,'Raw_Imigration data'!A:G, 7, FALSE) -> -545538 | C17: =VLOOKUP(A17,'Raw_Imigration data'!A:H, 8, FALSE) -> -218215.2 | D17: ='Raw_Gross Domestic Product '!Q3 -> 7639.7 | E17: =((D17-D16)/D16)*100 -> 4.8372489 | F17: ='Raw_Personal Income and Its Dis'!R3 -> 6283.4 | G17: =Raw_Unemployment!B17 -> 67.1 | H17: =B16 -> -159108 | I17: =E16 -> 6.2490887 | K17: =B17 -> -545538 | L17: =G17 -> 67.1 | M17: =H17 -> -159108 | P17: Coefficients | Q17: Standard Error | R17: t Stat | S17: P-value | T17: Lower 95% | U17: Upper 95% | V17: Lower 95.0% | W17: Upper 95.0% | Y17: =E17 -> 4.8372489 | Z17: =B17 -> -545538 | AA17: =H17 -> -159108 | AD17: =B17 -> -545538 | AE17: =D17 -> 7639.7 | AF17: =G17 -> 67.1
A18: 1996 | B18: =VLOOKUP(A18,'Raw_Imigration data'!A:G, 7, FALSE) -> -652127 | C18: =VLOOKUP(A18,'Raw_Imigration data'!A:H, 8, FALSE) -> -260850.8 | D18: ='Raw_Gross Domestic Product '!R3 -> 8073.1 | E18: =((D18-D17)/D17)*100 -> 5.6729976 | F18: ='Raw_Personal Income and Its Dis'!S3 -> 6666.2 | G18: =Raw_Unemployment!B18 -> 64.9 | H18: =B17 -> -545538 | I18: =E17 -> 4.8372489 | K18: =B18 -> -652127 | L18: =G18 -> 64.9 | M18: =H18 -> -545538 | O18: Intercept | P18: -4.3144372 | Q18: 4.9093933 | R18: -0.87881269 | S18: 0.38605437 | T18: -14.314544 | U18: 5.6856698 | V18: -14.314544 | W18: 5.6856698 | Y18: =E18 -> 5.6729976 | Z18: =B18 -> -652127 | AA18: =H18 -> -545538 | AD18: =B18 -> -652127 | AE18: =D18 -> 8073.1 | AF18: =G18 -> 64.9
A19: 1997 | B19: =VLOOKUP(A19,'Raw_Imigration data'!A:G, 7, FALSE) -> -687616 | C19: =VLOOKUP(A19,'Raw_Imigration data'!A:H, 8, FALSE) -> -275046.4 | D19: ='Raw_Gross Domestic Product '!S3 -> 8577.6 | E19: =((D19-D18)/D18)*100 -> 6.2491484 | F19: ='Raw_Personal Income and Its Dis'!T3 -> 7074 | G19: =Raw_Unemployment!B19 -> 59.3 | H19: =B18 -> -652127 | I19: =E18 -> 5.6729976 | K19: =B19 -> -687616 | L19: =G19 -> 59.3 | M19: =H19 -> -652127 | O19: Net Immigration | P19: -2.4616384e-06 | Q19: 3.8442702e-06 | R19: -0.64033959 | S19: 0.52651081 | T19: -1.029216e-05 | U19: 5.3688837e-06 | V19: -1.029216e-05 | W19: 5.3688837e-06 | Y19: =E19 -> 6.2491484 | Z19: =B19 -> -687616 | AA19: =H19 -> -652127 | AD19: =B19 -> -687616 | AE19: =D19 -> 8577.6 | AF19: =G19 -> 59.3
A20: 1998 | B20: =VLOOKUP(A20,'Raw_Imigration data'!A:G, 7, FALSE) -> -1015022 | C20: =VLOOKUP(A20,'Raw_Imigration data'!A:H, 8, FALSE) -> -406008.8 | D20: ='Raw_Gross Domestic Product '!T3 -> 9062.8 | E20: =((D20-D19)/D19)*100 -> 5.6565939 | F20: ='Raw_Personal Income and Its Dis'!U3 -> 7588.4 | G20: =Raw_Unemployment!B20 -> 54 | H20: =B19 -> -687616 | I20: =E19 -> 6.2491484 | K20: =B20 -> -1015022 | L20: =G20 -> 54 | M20: =H20 -> -687616 | O20: Unemployment Rate | P20: 0.10181284 | Q20: 0.060788739 | R20: 1.6748635 | S20: 0.10370822 | T20: -0.022009767 | U20: 0.22563545 | V20: -0.022009767 | W20: 0.22563545 | Y20: =E20 -> 5.6565939 | Z20: =B20 -> -1015022 | AA20: =H20 -> -687616 | AD20: =B20 -> -1015022 | AE20: =D20 -> 9062.8 | AF20: =G20 -> 54
A21: 1999 | B21: =VLOOKUP(A21,'Raw_Imigration data'!A:G, 7, FALSE) -> -1027905 | C21: =VLOOKUP(A21,'Raw_Imigration data'!A:H, 8, FALSE) -> -411162 | D21: ='Raw_Gross Domestic Product '!U3 -> 9631.2 | E21: =((D21-D20)/D20)*100 -> 6.2717924 | F21: ='Raw_Personal Income and Its Dis'!V3 -> 7978.6 | G21: =Raw_Unemployment!B21 -> 50.6 | H21: =B20 -> -1015022 | I21: =E20 -> 5.6565939 | K21: =B21 -> -1027905 | L21: =G21 -> 50.6 | M21: =H21 -> -1015022 | O21: Immigration Lag 1 | P21: -4.4932102e-06 | Q21: 4.1835745e-06 | R21: -1.0740122 | S21: 0.29084946 | T21: -1.3014873e-05 | U21: 4.0284522e-06 | V21: -1.3014873e-05 | W21: 4.0284522e-06 | Y21: =E21 -> 6.2717924 | Z21: =B21 -> -1027905 | AA21: =H21 -> -1015022 | AD21: =B21 -> -1027905 | AE21: =D21 -> 9631.2 | AF21: =G21 -> 50.6
A22: 2000 | B22: =VLOOKUP(A22,'Raw_Imigration data'!A:G, 7, FALSE) -> -951176 | C22: =VLOOKUP(A22,'Raw_Imigration data'!A:H, 8, FALSE) -> -380470.4 | D22: ='Raw_Gross Domestic Product '!V3 -> 10251 | E22: =((D22-D21)/D21)*100 -> 6.4353352 | F22: ='Raw_Personal Income and Its Dis'!W3 -> 8621.3 | G22: =Raw_Unemployment!B22 -> 47.6 | H22: =B21 -> -1027905 | I22: =E21 -> 6.2717924 | K22: =B22 -> -951176 | L22: =G22 -> 47.6 | M22: =H22 -> -1027905 | Y22: =E22 -> 6.4353352 | Z22: =B22 -> -951176 | AA22: =H22 -> -1027905 | AD22: =B22 -> -951176 | AE22: =D22 -> 10251 | AF22: =G22 -> 47.6
A23: 2001 | B23: =VLOOKUP(A23,'Raw_Imigration data'!A:G, 7, FALSE) -> -410575 | C23: =VLOOKUP(A23,'Raw_Imigration data'!A:H, 8, FALSE) -> -164230 | D23: ='Raw_Gross Domestic Product '!W3 -> 10581.9 | E23: =((D23-D22)/D22)*100 -> 3.2279778 | F23: ='Raw_Personal Income and Its Dis'!X3 -> 8993.1 | G23: =Raw_Unemployment!B23 -> 56.9 | H23: =B22 -> -951176 | I23: =E22 -> 6.4353352 | K23: =B23 -> -410575 | L23: =G23 -> 56.9 | M23: =H23 -> -951176 | Y23: =E23 -> 3.2279778 | Z23: =B23 -> -410575 | AA23: =H23 -> -951176 | AD23: =B23 -> -410575 | AE23: =D23 -> 10581.9 | AF23: =G23 -> 56.9
A24: 2002 | B24: =VLOOKUP(A24,'Raw_Imigration data'!A:G, 7, FALSE) -> -91143 | C24: =VLOOKUP(A24,'Raw_Imigration data'!A:H, 8, FALSE) -> -36457.2 | D24: ='Raw_Gross Domestic Product '!X3 -> 10929.1 | E24: =((D24-D23)/D23)*100 -> 3.2810743 | F24: ='Raw_Personal Income and Its Dis'!Y3 -> 9150 | G24: =Raw_Unemployment!B24 -> 69.4 | H24: =B23 -> -410575 | I24: =E23 -> 3.2279778 | K24: =B24 -> -91143 | L24: =G24 -> 69.4 | M24: =H24 -> -410575 | Y24: =E24 -> 3.2810743 | Z24: =B24 -> -91143 | AA24: =H24 -> -410575 | AD24: =B24 -> -91143 | AE24: =D24 -> 10929.1 | AF24: =G24 -> 69.4
A25: 2003 | B25: =VLOOKUP(A25,'Raw_Imigration data'!A:G, 7, FALSE) -> -424564 | C25: =VLOOKUP(A25,'Raw_Imigration data'!A:H, 8, FALSE) -> -169825.6 | D25: ='Raw_Gross Domestic Product '!Y3 -> 11456.5 | E25: =((D25-D24)/D24)*100 -> 4.825649 | F25: ='Raw_Personal Income and Its Dis'!Z3 -> 9481.8 | G25: =Raw_Unemployment!B25 -> 71.9 | H25: =B24 -> -91143 | I25: =E24 -> 3.2810743 | K25: =B25 -> -424564 | L25: =G25 -> 71.9 | M25: =H25 -> -91143 | O25: SUMMARY OUTPUT | P25: Model 2 | Y25: =E25 -> 4.825649 | Z25: =B25 -> -424564 | AA25: =H25 -> -91143 | AD25: =B25 -> -424564 | AE25: =D25 -> 11456.5 | AF25: =G25 -> 71.9
